Workbook

Sheet 00 Cover
A1: MaxBid
A2: Strategic Project Workbook | maxbid.com.au
A4: Prepared for | B4: Ashleigh Phillips and Jason
A5: Version | B5: 0.1 Draft for review
A6: Date | B6: 22 September 2026
A7: Status | B7: Design phase. Visual design signed off on 22 September 2026. No build work until the full workbook is signed off.
A8: Design prototypes | B8: https://claude.ai/artifact/T6x3BarxFAz2nA7G7DyMAp The Chosen homepage and Main pages in this canvas are the signed off designs. Other pages in the canvas are explored options kept for reference.
A9: Purpose | B9: Single source of truth for what we are building: scope, features, valuation logic, data sources, database, tech stack, design, commercial model, risks and the build roadmap.
A10: How to use | B10: Each tab covers one topic. Tab 02 records every decision made, so any later change is made there first and flows into the other tabs. Tab 10 is a live calculator that proves the bid maths with formulas.
A11: Cell legend | B11: Blue text on yellow fill means an input you can change. Black text means a formula or fixed content. Values marked Estimate must be validated during the MVP.
A13: Contents
A14: 01 Summary | B14: Vision, problem, solution, positioning and MVP goals
A15: 02 Decisions | B15: Register of every decision made in the discovery session
A16: 03 Users | B16: Target users and personas
A17: 04 Competitors | B17: Existing tools and the gap we fill
A18: 05 Scope | B18: What is in V1, what is deferred and what is excluded
A19: 06 User Journey | B19: End to end workflow from catalogue link to recorded outcome
A20: 07 Features | B20: Full feature register with priority, phase and acceptance criteria
A21: 08 Matching Logic | B21: Match levels, evidence weighting, confidence scoring and resale scenarios
A22: 09 Cost Fields | B22: Every cost line in the calculator, its source and GST treatment
A23: 10 Profit Calculator | B23: Working model of the bid engine with live formulas and a sensitivity table
A24: 11 Data Sources | B24: Where every data point comes from and how it is obtained
A25: 12 Pipeline | B25: Processing stages, jobs, AI usage and outputs
... A52: 39 Build Architecture | B52: Monorepo, component library, file size rules, mobile first rules and performance budgets

Sheet 01 Summary
A1: Executive Summary
A3: Name | B3: MaxBid at maxbid.com.au. App at app.maxbid.com.au.
A4: Vision | B4: A decision support platform that turns any supported Australian auction catalogue into a ranked list of buying opportunities, each with evidenced market values, full acquisition costs and a safe maximum bid.
A5: Problem | B5: Resellers buying at auction guess at resale value, forget costs such as buyer's premium, GST, transport and repairs, and bid on emotion in the final seconds. Researching every lot manually across eBay, retailers and past auction results takes hours per catalogue.
A6: Solution | B6: Paste a catalogue link or upload a PDF. The platform extracts every lot, runs a fast triage to rank opportunities, then performs deep analysis on the lots the user shortlists. Deep analysis identifies the item using text and photos, finds comparable sold and advertised prices, explains exactly what each comparable is and how it differs, and calculates target, absolute maximum and break even bids against the user's own costs and profit goal.
A7: Core principle | B7: Transparency over false precision. Every value shows its evidence, the match level, the differences and a confidence rating. The system never presents a weak estimate as a verified value.
A8: Primary user | B8: Resellers and flippers buying at auction for profit in Australia.
A9: Launch sources | B9: Grays, Pickles and Lloyds, plus PDF catalogue upload as a universal fallback.
A10: Category scope | B10: All auction categories, using a category agnostic matching engine with category specific valuation rules added progressively.
A11: Build approach | B11: Built in house by Ashleigh using Claude Code and Codex on Next.js, Supabase and Vercel. Used internally first, commercialised once proven.
A12: MVP goal | B12: Internal MVP in six to eight weeks that we use on real auctions, recording actual outcomes to measure valuation accuracy before any public launch.
A13: Commercial path | B13: Subscription tiers with included deep analysis credits and top up packs. Free triage as the entry point.
A14: Defensibility | B14: The long term moat is the accumulated database of identified products, comparables, user corrections and verified sold outcomes. Every analysis makes the next one more accurate.

Sheet 02 Decisions
A1: Decision Register
A2: Every decision from the discovery session. Change decisions here first.
A4: ID | B4: Area | C4: Question | D4: Decision | E4: Followed recommendation | F4: Rationale and implications
A5: D01 | B5: Strategy | C5: Primary goal | D5: Build for us first, commercialise once proven | E5: Yes | F5: Proves accuracy on real money before selling it. Keeps early costs low.
A6: D02 | B6: Strategy | C6: V1 market | D6: All auction categories | E6: No | F6: Broader appeal. Requires a category agnostic engine and progressive category rules. Accuracy will vary by category and must be shown honestly.
A7: D03 | B7: Strategy | C7: Primary paying user | D7: Resellers and flippers buying for profit | E7: n/a | F7: Profit maths and bid limits are the core of the product.
A8: D04 | B8: Input | C8: Auction sources in V1 | D8: Grays, Pickles and Lloyds | E8: Yes | F8: Three structured, high volume sources. Each needs its own extractor.
A9: D05 | B9: Input | C9: Submission method | D9: URL plus PDF catalogue upload | E9: Yes | F9: PDF upload covers any auctioneer not yet supported.
A10: D06 | B10: Input | C10: Geographic scope | D10: Australia only | E10: Yes | F10: Consistent currency, GST, freight and comparables.
A11: D07 | B11: Data | C11: Comparable price gathering | D11: eBay API, web search API and retailer sites | E11: Yes | F11: Uses official APIs where possible and limits scraping risk.
A12: D08 | B12: Data | C12: Sold versus advertised weighting | D12: Sold prices weighted highest, advertised as support | E12: Yes | F12: Sold prices are evidence of what buyers actually pay.
A13: D09 | B13: Data | C13: Pricing freshness | D13: Live on each analysis, cached for seven days | E13: Yes | F13: All comparables are also stored permanently for the evidence trail, which builds a historical database at no extra cost.
A14: D10 | B14: Identification | C14: Lot identification method | D14: Text plus AI vision on lot photos | E14: Yes | F14: Model numbers are often only visible on plates in photos.
A15: D11 | B15: Identification | C15: User correction | D15: Always let the user confirm or edit the identification | E15: Yes | F15: Corrections become matching data that improves future results.
... A42: D38 | B42: Design | C42: Visual style | D42: Clean, data dense trading desk feel | E42: Yes | F42: Numbers first, calm colours, clear status signals.
A43: D39 | B43: Design | C43: Theme | D43: Light and dark mode following system | E43: Yes
A44: D40 | B44: Commercial | C44: Pricing model | D44: Subscription tiers with included credits and top up packs | E44: Yes | F44: Predictable revenue with usage based cost control.
A45: D41 | B45: Commercial | C45: Free entry | D45: Free triage with limited catalogues, pay for deep analysis | E45: Yes | F45: Users see value before paying.
A46: D42 | B46: Commercial | C46: Name | D46: Suggestions provided in this workbook | E46: Yes | F46: See tab 21.
A47: D43 | B47: Legal | C47: Positioning | D47: Decision support tool, not valuation advice | E47: Yes | F47: Clear disclaimers in the product and the terms.
A48: D44 | B48: Legal | C48: Comparable display | D48: Link, price, date and text summary. No copied images | E48: Yes | F48: Avoids copyright issues with third party photos.
A49: D45 | B49: Legal | C49: Auction data access | D49: Respect site terms, rate limit, public pages only | E49: Yes | F49: Formal partnerships considered once there is traction.
A50: D46 | B50: Delivery | C50: Builder | D50: Ashleigh with Claude Code and Codex | E50: Yes
A51: D47 | B51: Delivery | C51: Timeline | D51: Internal MVP in six to eight weeks, then iterate | E51: Yes
A52: D48 | B52: Delivery | C52: Workbook format | D52: Excel with tabs by topic | E52: n/a | F52: This file.
A53: D49 | B53: Configuration | C53: Configuration layers | D53: Platform, Organisation, User, Lot. Each lower layer overrides the one above unless locked | E53: Yes | F53: Resolution engine reads the lowest set value. See tab 27.
A54: D50 | B54: Configuration | C54: Reach of a user override | D54: That lot, in their organisation only | E54: Yes | F54: Overrides never change defaults or other lots.
A55: D51 | B55: Configuration | C55: User corrections to shared data | D55: Never applied directly. Flagged for admin review, then applied | E55: Yes | F55: Protects every other user from one person's error. See tab 31.
A56: D52 | B56: Configuration | C56: Evidence weights, match levels, confidence formula | D56: Hard coded, versioned and visible to users | E56: Yes | F56: Changed only by a versioned release with a public changelog.
A57: D53 | B57: Configuration | C57: Core maths and GST rate | D57: Hard coded, never overridable | E57: Yes | F57: A legislative GST change is handled by a code release.
A58: D54 | B58: Helper behaviour | C58: User enters own resale price | D58: Allowed. Labelled Your input with system confidence shown separately | E58: Yes | F58: The user may know more than the evidence. The system never presents their figure as its own.
A59: D55 | B59: Helper behaviour | C59: Bid above absolute maximum or break even | D59: Warn and let them proceed | E59: Yes | F59: The platform advises and never blocks a bidding decision.
A60: D56 | B60: Helper behaviour | C60: Insufficient evidence | D60: No system bid. User can enter own resale to calculate | E60: Yes
A61: D57 | B61: Helper behaviour | C61: Excluding comparables | D61: Allowed with reason recorded and valuation shown before and after | E61: Yes
A62: D58 | B62: Helper behaviour | C62: User supplied comparables | D62: Allowed. Labelled User supplied, own weight category, private to the organisation | E62: Yes | F62: Never shared with other organisations.
A63: D59 | B63: Helper behaviour | C63: Overridden value display | D63: Marker on every overridden field with one click reset to system value | E63: Yes
A64: D60 | B64: Helper behaviour | C64: Override summary | D64: Per lot summary of what has changed from the system values | E64: Yes
A65: D61 | B65: Transparency | C65: Provenance labels | D65: Every figure tagged Verified, Extracted, Estimated or Your input | E65: Yes | F65: Definitions on tab 29.
A66: D62 | B66: Transparency | C66: Negative evidence | D66: List sources searched and what was not found | E66: Yes
A67: D63 | B67: Transparency | C67: Data age | D67: Date checked on every price with a stale warning after seven days | E67: Yes
...

Sheet 03 Users
A1: Target Users and Personas
A3: ID | B3: Priority | C3: Persona | D3: Description | E3: Main pain points | F3: What they need most | G3: Likely tier
A4: P1 | B4: Primary | C4: Part time reseller | D4: Buys a few lots a month on Grays and Pickles and resells on eBay, Facebook Marketplace and Gumtree. | E4: Overpaying, forgetting costs, time spent researching each lot. | F4: Fast triage, clear target bid, mobile bid sheet. | G4: Starter
A5: P2 | B5: Primary | C5: Full time flipper | D5: Treats auction buying as a business. Reviews many catalogues each week across categories. | E5: Volume of lots, cash flow, GST treatment, tracking actual margins. | F5: Bulk triage, cost profiles, GST cash view, outcome tracking and margin history. | G5: Pro
A6: P3 | B6: Internal | C6: Us (Ashleigh and Jason) | D6: Buying machinery, tools and general stock, including woodworking equipment for Perth Cabinet Doors. | E6: Knowing what a machine is really worth before committing. | F6: Accurate machinery matching and evidence trail. | G6: Internal
A7: P4 | B7: Secondary | C7: Dealer or liquidator | D7: Buys in volume with several staff reviewing catalogues. | E7: Consistency across buyers, approval before bidding, team visibility. | F7: Team accounts, shared watchlists, roles, exports. | G7: Dealer
A8: P5 | B8: Secondary | C8: Trade business buyer | D8: Buys equipment for own use rather than resale. | E8: Knowing a fair price compared with buying new or used elsewhere. | F8: New price and cheapest available comparison. | G8: Starter

Sheet 04 Competitors
A1: Competitor Landscape
A2: Based on the earlier research. Recheck before launch.
A3: Tool | B3: What it does | C3: Gap | D3: Relevance to us
A4: eBay Product Research | B4: Sold price history, price ranges, shipping and sell through rates for eBay listings. | C4: eBay only. No auction catalogue input, no acquisition cost or bid calculation. | D4: Data source for us rather than a direct competitor.
A5: Machinio | B5: Aggregates used machinery listings, specifications and advertised prices worldwide. | C5: Advertised prices only. No catalogue analysis or bid limits. | D5: Possible reference source for machinery comparables.
A6: EquipmentWatch | B6: Professional valuations for heavy equipment, with API access. | C6: Heavy equipment focus and professional pricing. No auction workflow. | D6: Possible paid data partner later for plant and heavy equipment.
A7: WorthPoint | B7: Realised auction results for antiques and collectibles. | C7: Collectibles only. No cost or bid engine. | D7: Possible reference for collectibles category.
A8: Manual research | B8: Google, eBay and dealer sites searched lot by lot. | C8: Slow, inconsistent, no cost modelling, no evidence record. | D8: This is the real incumbent we replace.
A10: Our position | B10: No known tool takes an Australian auction catalogue, assesses every lot, calculates full acquisition costs and tells a reseller what to bid with evidenced, confidence rated comparables.

Sheet 05 Scope
A1: Scope
A2: V1 is the internal MVP. V2 is the commercial launch. Later covers growth features.
A3: Area | B3: In V1 (internal MVP) | C3: V2 and later | D3: Excluded
A4: Catalogue input | B4: Grays, Pickles and Lloyds URLs. PDF catalogue upload. | C4: Slattery, Manheim, other auction houses. Browser extension. | D4: Facebook groups and private sales.
A5: Lot processing | B5: Extraction, triage of all lots, deep analysis of shortlisted lots. | C5: Scheduled re analysis before close. Bulk deep analysis.
A6: Identification | B6: Text and photo vision identification with user confirmation. | C6: Category specific identification rules such as VIN and rego lookup for vehicles.
A7: Comparables | B7: eBay active listings, web search results, retailer pages, auction realised results, internal outcome data. | C7: eBay Marketplace Insights sold data if approved. Paid data partners for heavy equipment. | D7: Scraping of sites whose terms prohibit it.
A8: Valuation | B8: Match levels, evidence weighting, confidence score, conservative, expected and optimistic resale. | C8: Category specific depreciation and condition models. | D8: Formal valuation certificates.
A9: Calculator | B9: Target, absolute maximum and break even bids. Profit slider. Editable cost lines. GST by profile. Cost profiles. Transport estimate. | C9: Automatic channel selling fees as an optional helper.
A10: After analysis | B10: Watchlist, closing soon alerts, outcome recording, PDF bid sheet, CSV export. | C10: Saved search alerts for new undervalued lots. Price drop alerts. Margin dashboard. | D10: Automated bidding on behalf of users.
A11: Accounts | B11: Organisations with members and roles. Email and Google sign in. | C11: Stripe billing, credits, top ups, free tier limits. | D11: Enterprise SSO.
A12: Platforms | B12: Mobile first responsive web app. Installable progressive web app with offline watchlist and bid view. | C12: Richer offline support. | D12: Native mobile apps.
A13: Geography | B13: Australia. | C13: New Zealand. | D13: Global.

Sheet 06 User Journey
A1: User Journey
A2: End to end flow for a reseller analysing one catalogue
A3: Step | B3: Stage | C3: What the user does | D3: What the system does | E3: Screen
A4: 1 | B4: Submit | C4: User pastes an auction URL or uploads a PDF and selects a cost profile. | D4: Platform detected, auction created, analysis job queued. | E4: Submit screen
A5: 2 | B5: Extract | C5: User sees a progress bar and can leave the page. | D5: Lots, photos, descriptions, locations, closing times, current bids and buyer's premium terms extracted. | E5: Analysis progress
A6: 3 | B6: Triage | C6: User receives an email and opens the ranked triage list. | D6: Quick identification, rough resale range, rough max bid and opportunity score for every lot. | E6: Triage table
A7: 4 | B7: Filter and shortlist | C7: User filters by category, value, location and closing time and ticks lots for deep analysis. Credit cost shown before confirming. | D7: Deep analysis jobs queued per lot. | E7: Triage table
A8: 5 | B8: Deep analysis | C8: User waits or returns later. Lots fill in as they complete. | D8: Vision identification, comparable search, match grading, valuation and bid calculation. | E8: Lot detail
A9: 6 | B9: Confirm identification | C9: User confirms or corrects the identified product. | D9: Correction stored. Lot revalued automatically. | E9: Lot detail
A10: 7 | B10: Review evidence | C10: User reads the match explanation and opens comparable links. | D10: Evidence shown with match level, differences, date checked and confidence. | E10: Lot detail, evidence panel
A11: 8 | B11: Adjust costs and profit | C11: User expands cost lines, edits repairs or transport, sets profit in dollars or percentage, moves the bid slider. | D11: Target, absolute maximum and break even bids recalculate instantly. | E11: Lot detail, calculator
A12: 9 | B12: Watch and export | C12: User adds lots to the watchlist and downloads the PDF bid sheet. | D12: Closing soon alerts scheduled. Bid sheet generated. | E12: Watchlist, export
A13: 10 | B13: Bid | C13: User bids on the auction site using the mobile bid view. | D13: Mobile view shows lot, target bid, absolute maximum and a clear stop line. | E13: Mobile bid view
A14: 11 | B14: Record outcome | C14: User records won or lost, final hammer price and later the actual resale price. | D14: Outcome stored as verified evidence and used to measure accuracy. | E14: Outcomes

Sheet 07 Features
A1: Feature Register
A2: Priority uses MoSCoW. Phase 1 is the internal MVP.
A3: ID | B3: Module | C3: Feature | D3: Description | E3: Priority | F3: Phase | G3: Depends on | H3: Acceptance criteria
A4: F01 | B4: Accounts | C4: Sign in | D4: Email magic link and Google sign in through Supabase Auth. | E4: Must | F4: 1 | H4: User can sign in and out on desktop and mobile.
A5: F02 | B5: Accounts | C5: Organisations | D5: Every user belongs to an organisation. Data is scoped to the organisation. | E5: Must | F5: 1 | G5: Sign in | H5: Two members of one organisation see the same analyses. Other organisations see nothing.
A6: F03 | B6: Accounts | C6: Roles | D6: Owner, admin, buyer and viewer roles. | E6: Should | F6: 1 | G6: Organisations | H6: Viewer cannot edit costs or spend credits.
A7: F04 | B7: Accounts | C7: Profile settings | D7: GST registered, base location, default cost profile, default profit target. | E7: Must | F7: 1 | G7: Organisations | H7: Changing GST registration recalculates all open lots.
A8: F05 | B8: Input | C8: URL submission | D8: Paste a Grays, Pickles or Lloyds URL. Platform detected automatically. | E8: Must | F8: 1 | H8: Unsupported URLs show a clear message and offer PDF upload.
A9: F06 | B9: Input | C9: PDF upload | D9: Upload an auction catalogue PDF for extraction. | E9: Must | F9: 1 | H9: Lots extracted from a text PDF and a scanned PDF with at least 90 percent completeness in testing.
A10: F07 | B10: Input | C10: Grays extractor | D10: Structured extraction of lots, photos, location, closing time, current bid and terms. | E10: Must | F10: 1 | G10: Extraction service | H10: All lots from a 300 lot catalogue extracted with correct lot numbers.
A11: F08 | B11: Input | C11: Pickles extractor | D11: As above for Pickles. | E11: Must | F11: 1 | G11: Extraction service | H11: As above.
A12: F09 | B12: Input | C12: Lloyds extractor | D12: As above for Lloyds. | E12: Must | F12: 1 | G12: Extraction service | H12: As above.
A13: F10 | B13: Input | C13: Buyer's premium extraction | D13: Read premium rates and GST terms from each auction's terms. Fall back to platform default. | E13: Must | F13: 1 | G13: Extractors | H13: Premium shown with its source and is editable.
A14: F11 | B14: Processing | C14: Background jobs | D14: Durable jobs with retries and fan out per lot. | E14: Must | F14: 1 | H14: A failed lot retries without restarting the catalogue.
A15: F12 | B15: Processing | C15: Progress and email | D15: Live progress bar and email when triage completes. | E15: Must | F15: 1 | G15: Background jobs | H15: Email arrives within five minutes of completion.
A16: F13 | B16: Triage | C16: Quick identification | D16: Low cost model identifies each lot from text and the primary photo. | E16: Must | F16: 1 | G16: Background jobs | H16: Category and product type assigned to every lot.
A17: F14 | B17: Triage | C17: Rough valuation | D17: One search pass returns a rough resale range and rough max bid. | E17: Must | F17: 1 | G17: Quick identification | H17: Range shown with a triage confidence label.
A18: F15 | B18: Triage | C18: Opportunity score | D18: Score from 0 to 100 ranking lots by likely margin and confidence. | E18: Must | F18: 1 | G18: Rough valuation | H18: Table sorted by score by default.
A19: F16 | B19: Triage | C19: Filters | D19: Category, value range, location and closing time. | E19: Must | F19: 1 | G19: Triage table | H19: Filters combine and persist for the session.
A20: F17 | B20: Triage | C20: Shortlist and credit preview | D20: Tick lots for deep analysis. Show credits required before confirming. | E20: Must | F20: 1 | G20: Credits ledger | H20: User cannot exceed available credits.
A21: F18 | B21: Deep analysis | C21: Vision identification | D21: Larger model reads all lot photos including data plates and labels. | E21: Must | F21: 1 | G21: Background jobs | H21: Brand and model extracted from plate photos in testing.
A22: F19 | B22: Deep analysis | C22: Identification confirmation | D22: User confirms or edits brand, model, year, specs and condition. | E22: Must | F22: 1 | G22: Vision identification | H22: Edit triggers automatic revaluation.
A23: F20 | B23: Deep analysis | C23: Comparable search | D23: Search eBay, web search API, retailer pages, auction realised results and internal data. | E23: Must | F23: 1 | G23: Data sources | H23: Each lot returns up to 15 candidate comparables.
A24: F21 | B24: Deep analysis | C24: Match grading | D24: Assign match level, reason and differences to each comparable. | E24: Must | F24: 1 | G24: Comparable search | H24: Every comparable shows a match level and a plain English reason.
A25: F22 | B25: Deep analysis | C25: New price lookup | D25: Find current or last known new retail price. | E25: Should | F25: 1 | G25: Comparable search | H25: New price shown with source and date or marked not found.
A26: F23 | B26: Deep analysis | C26: Cheapest currently advertised | D26: Lowest current advertised comparable of similar specification. | E26: Must | F26: 1 | G26: Match grading | H26: Shown with link, match level and date checked.
... A37: F34 | B37: Calculator | C37: Transport estimate | D37: Distance from base to lot location multiplied by rate per km plus base fee by size class. | E37: Should | F37: 1 | G37: Routing API | H37: Estimate shown with distance and editable.
A38: F35 | B38: After analysis | C38: Watchlist | D38: Save lots across auctions. | E38: Must | F38: 1 | H38: Watchlist shows live closing countdown.
A39: F36 | B39: After analysis | C39: Closing soon alerts | D39: Email and push alerts before a watchlisted lot closes. | E39: Should | F39: 1 | G39: Watchlist | H39: Alert timing set by the user.
A40: F37 | B40: After analysis | C40: Outcome recording | D40: Won or lost, hammer price, actual resale price and date. | E40: Must | F40: 1 | H40: Outcome feeds internal comparables.
A41: F38 | B41: After analysis | C41: PDF bid sheet | D41: One line per lot with target and absolute maximum, readable on a phone. | E41: Must | F41: 1 | G41: Bid limits | H41: Generates in under ten seconds for 50 lots.
A42: F39 | B42: After analysis | C42: CSV export | D42: Full lot data with costs and bids. | E42: Should | F42: 1 | H42: Opens cleanly in Excel.
A43: F40 | B43: Mobile | C43: Mobile bid view | D43: Large type view of watchlisted lots with target, maximum and stop line. | E43: Must | F43: 1 | G43: Watchlist | H43: Usable one handed on a phone.
A44: F41 | B44: Admin | C44: Platform admin | D44: Manage auction platforms, premium defaults, categories and extractor health. | E44: Should | F44: 1 | H44: Admin can update a platform default without a deploy.
A45: F42 | B45: Admin | C45: Cost and usage logging | D45: Record AI, search and extraction cost per job. | E45: Must | F45: 1 | G45: Background jobs | H45: Cost per catalogue visible in admin.
A46: F43 | B46: Billing | C46: Stripe subscriptions | D46: Tiers with monthly credit allowance. | E46: Must | F46: 2 | G46: Organisations | H46: Credits granted on renewal.
A47: F44 | B47: Billing | C47: Top up packs | D47: One off credit purchases. | E47: Should | F47: 2 | G47: Stripe subscriptions | H47: Credits available immediately after payment.
A48: F45 | B48: Billing | C48: Free tier limits | D48: Limited triage catalogues and starter credits. | E48: Must | F48: 2 | G48: Stripe subscriptions | H48: Limits enforced server side.
A49: F46 | B49: Growth | C49: Saved search alerts | D49: Alert when a new lot matches saved criteria with a high opportunity score. | E49: Could | F49: 3 | G49: Triage
A50: F47 | B50: Growth | C50: Margin dashboard | D50: Actual versus predicted margin over time. | E50: Could | F50: 3 | G50: Outcome recording
...

Sheet 08 Matching Logic
A1: Matching, Evidence and Confidence Logic
A2: Starting weights. Calibrate against recorded outcomes during the MVP.
A4: Match levels
A5: Match level | B5: Definition | C5: Match weight | D5: Price adjustment | E5: Standard explanation text
A6: Exact | B6: Same brand, model and material specification. | C6: 1 | D6: None | E6: Exact match. Same brand, model and specification.
A7: Near exact | B7: Same model with a minor year or specification difference. | C7: 0.85 | D7: Small adjustment where the difference is known | E7: Same model. Differs in year or a minor option.
A8: Higher specification | B8: Comparable has greater capacity, features or performance. | C8: 0.6 | D8: Adjust price downward | E8: No exact match found. This comparable has more features, so it may overstate value.
A9: Lower specification | B9: Comparable has fewer features or lower capacity. | C9: 0.6 | D9: Adjust price upward | E9: No exact match found. This comparable has fewer features, so it may understate value.
A10: Similar alternative | B10: Different brand or model with broadly comparable capability. | C10: 0.4 | D10: Adjust by brand tier where known | E10: Different brand or model with similar capability. Treat as a guide only.
A11: Insufficient evidence | B11: No defensible comparable located. | C11: 0 | D11: Not used | E11: We could not find a reliable comparable. Enter your own resale estimate to calculate a bid.
A13: Evidence type weights
A14: Evidence type | B14: Description | C14: Evidence weight | D14: Used for
A15: Verified outcome (own organisation) | B15: Actual resale recorded by the user's organisation. | C15: 1 | D15: Resale
A16: Auction realised result | B16: Hammer price from a past Grays, Pickles or Lloyds auction, adjusted for premium. | C16: 0.95 | D16: Resale floor and auction market
A17: Marketplace sold listing | B17: Completed sale on eBay or similar, where access is available. | C17: 0.95 | D17: Resale
A18: Verified outcome (pooled, anonymised) | B18: Outcomes from other organisations, anonymised. Later phase. | C18: 0.85 | D18: Resale
A19: Used advertised listing | B19: Current asking price for a used item. | C19: 0.6 | D19: Resale ceiling. Apply asking to selling discount.
A20: User supplied comparable | B20: Link or price added by the user's organisation. Private to that organisation. | C20: 0.5 | D20: Resale, that organisation only
A21: New retail price | B21: Current or last known new price. | C21: 0 | D21: Reference only. Not used for resale.
A23: Recency decay
A24: Evidence age | B24: Recency weight
A25: 0 to 90 days | B25: 1
A26: 91 to 180 days | B26: 0.8
A27: 181 to 365 days | B27: 0.6
A28: Over 365 days | B28: 0.4
A30: Combined weight and resale scenarios
A31: Comparable weight | B31: Match weight multiplied by evidence weight multiplied by recency weight.
A32: Asking to selling discount | B32: Advertised used prices are reduced by a category default, starting at 10 percent, before weighting. Editable in admin.
A33: Conservative resale | B33: Weighted 25th percentile of adjusted comparable prices.
A34: Expected resale | B34: Weighted median of adjusted comparable prices.
A35: Optimistic resale | B35: Weighted 75th percentile of adjusted comparable prices.
A36: Minimum evidence | B36: At least three comparables with a combined weight of 1.5 or more before a scenario range is shown. Otherwise the lot is marked Low or Insufficient.
A37: Optimism flag | B37: If the user's profit target is only met on the optimistic scenario, the lot shows a visible warning.
A39: Confidence score (0 to 100)
A40: Component | B40: Calculation | C40: Weight
A41: Identification confidence | B41: Model confidence in brand and model, raised to 100 when user confirmed. | C41: 0.25
A42: Best match level | B42: Weight of the best comparable's match level multiplied by 100. | C42: 0.25
A43: Evidence volume | B43: Combined comparable weight, capped at 5, scaled to 100. | C43: 0.2
A44: Sold evidence share | B44: Share of combined weight coming from sold or realised evidence. | C44: 0.15
A45: Price agreement | B45: 100 minus coefficient of variation of adjusted prices, floored at zero. | C45: 0.15
...

Sheet 09 Cost Fields
A1: Cost Field Specification
A3: Field | B3: Source | C3: Default | D3: Editable per lot | E3: GST treatment
A4: Expected resale price | B4: System (scenario), editable | C4: Selected scenario | D4: Yes | E4: Entered GST inclusive. Registered users net off GST.
A5: Hammer price | B5: User or slider | C5: Target bid | D5: Yes | E5: GST added when the auction terms say the lot attracts GST.
A6: Buyer's premium rate | B6: Extracted from auction terms | C6: Platform default fallback | D6: Yes | E6: Usually attracts GST. Flag editable.
A7: GST on hammer | B7: Extracted | C7: From auction terms | D7: Yes | E7: Creditable for registered users.
A8: GST on premium | B8: Extracted | C8: From auction terms | D8: Yes | E8: Creditable for registered users.
A9: Transport | B9: Distance estimate | C9: Rate per km and base fee by size class from cost profile | D9: Yes | E9: Entered GST inclusive.
A10: Removal or crane | B10: User | C10: Cost profile | D10: Yes | E10: Entered GST inclusive.
A11: Repairs | B11: User | C11: Cost profile, dollars or percentage of resale | D11: Yes | E11: Entered GST inclusive.
A12: Replacement parts | B12: User | C12: Zero | D12: Yes | E12: Entered GST inclusive.
A13: Testing or certification | B13: User | C13: Cost profile | D13: Yes | E13: Entered GST inclusive.
A14: Cleaning and preparation | B14: User | C14: Cost profile | D14: Yes | E14: Entered GST inclusive.
... A19: Minimum acceptable profit | B19: User | C19: Profile default | D19: Yes | E19: Drives absolute maximum bid.

Sheet 10 Profit Calculator
A1: Profit and Bid Calculator
A2: Working model of the bid engine. Change the yellow cells. Example values are illustrative only.
A3: Settings (from user profile and lot) | E3: Bid sensitivity (slider preview)
A4: GST registered | B4: Yes | C4: Profile setting. Yes or No. | E4: % of target | F4: Hammer bid | G4: Effective acquisition cost | H4: Estimated profit | I4: Return on cost | J4: Zone
A5: GST rate | B5: 0.1 | C5: Australian GST. | E5: 0.6 | F5: =$B$46*E5 -> 4761.6075 | G5: =F5*$B$43+$B$38 -> 9120 | H5: =$B$19-G5 -> 7698.1818 | I5: =IF(G5=0,0,H5/G5) -> 0.84409888 | J5: =IF(H5>=IF($B$7="$",$B$8,$B$9*G5)-0.5,"Green",IF(H5>0,"Amber","Red")) -> Green
A6: Resale scenario | B6: Conservative | C6: Conservative, Expected or Optimistic. | E6: 0.7 | F6: =$B$46*E6 -> 5555.2087 | G6: =F6*$B$43+$B$38 -> 10044.545 | H6: =$B$19-G6 -> 6773.6364 | I6: =IF(G6=0,0,H6/G6) -> 0.67435967 | J6: =IF(H6>=IF($B$7="$",$B$8,$B$9*G6)-0.5,"Green",IF(H6>0,"Amber","Red")) -> Green
A7: Profit target type | B7: $ | C7: $ for dollars or % for return on cost. | E7: 0.8 | F7: =$B$46*E7 -> 6348.81 | G7: =F7*$B$43+$B$38 -> 10969.091 | H7: =$B$19-G7 -> 5849.0909 | I7: =IF(G7=0,0,H7/G7) -> 0.53323388 | J7: =IF(H7>=IF($B$7="$",$B$8,$B$9*G7)-0.5,"Green",IF(H7>0,"Amber","Red")) -> Green
A8: Target profit ($) | B8: 4000 | C8: Used when type is $. | E8: 0.9 | F8: =$B$46*E8 -> 7142.4112 | G8: =F8*$B$43+$B$38 -> 11893.636 | H8: =$B$19-G8 -> 4924.5455 | I8: =IF(G8=0,0,H8/G8) -> 0.41404877 | J8: =IF(H8>=IF($B$7="$",$B$8,$B$9*G8)-0.5,"Green",IF(H8>0,"Amber","Red")) -> Green
A9: Target return on cost (%) | B9: 0.25 | C9: Used when type is %. | E9: 1 | F9: =$B$46*E9 -> 7936.0125 | G9: =F9*$B$43+$B$38 -> 12818.182 | H9: =$B$19-G9 -> 4000 | I9: =IF(G9=0,0,H9/G9) -> 0.31205674 | J9: =IF(H9>=IF($B$7="$",$B$8,$B$9*G9)-0.5,"Green",IF(H9>0,"Amber","Red")) -> Green
A10: Minimum acceptable profit ($) | B10: 1500 | C10: Drives absolute maximum when type is $. | E10: 1.1 | F10: =$B$46*E10 -> 8729.6137 | G10: =F10*$B$43+$B$38 -> 13742.727 | H10: =$B$19-G10 -> 3075.4545 | I10: =IF(G10=0,0,H10/G10) -> 0.22378779 | J10: =IF(H10>=IF($B$7="$",$B$8,$B$9*G10)-0.5,"Green",IF(H10>0,"Amber","Red")) -> Amber
A11: Minimum acceptable return (%) | B11: 0.1 | C11: Drives absolute maximum when type is %. | E11: 1.2 | F11: =$B$46*E11 -> 9523.215 | G11: =F11*$B$43+$B$38 -> 14667.273 | H11: =$B$19-G11 -> 2150.9091 | I11: =IF(G11=0,0,H11/G11) -> 0.14664683 | J11: =IF(H11>=IF($B$7="$",$B$8,$B$9*G11)-0.5,"Green",IF(H11>0,"Amber","Red")) -> Amber
E12: 1.3 | F12: =$B$46*E12 -> 10316.816 | G12: =F12*$B$43+$B$38 -> 15591.818 | H12: =$B$19-G12 -> 1226.3636 | I12: =IF(G12=0,0,H12/G12) -> 0.078654306 | J12: =IF(H12>=IF($B$7="$",$B$8,$B$9*G12)-0.5,"Green",IF(H12>0,"Amber","Red")) -> Amber
A13: Resale evidence (GST inclusive prices) | E13: 1.4 | F13: =$B$46*E13 -> 11110.417 | G13: =F13*$B$43+$B$38 -> 16516.364 | H13: =$B$19-G13 -> 301.81818 | I13: =IF(G13=0,0,H13/G13) -> 0.018273888 | J13: =IF(H13>=IF($B$7="$",$B$8,$B$9*G13)-0.5,"Green",IF(H13>0,"Amber","Red")) -> Amber
A14: Conservative resale | B14: 18500 | C14: System value from tab 08 logic.
A15: Expected resale | B15: 21000 | E15: Zones: Green meets the profit target. Amber is profitable but below target. Red is break even or a loss.
A16: Optimistic resale | B16: 24000 | E16: In the app the slider is continuous. This table previews the same maths at fixed steps.
A17: Resale price includes GST | B17: Yes | C17: Yes if the price the item sells for includes GST.
A18: Selected resale price | B18: =IF(B6="Conservative",B14,IF(B6="Expected",B15,B16)) -> 18500
A19: Net resale used for profit | B19: =IF(AND(B4="Yes",B17="Yes"),B18/(1+B5),B18) -> 16818.182 | C19: Registered users remit GST on the sale, so profit uses the GST exclusive amount.
A21: Auction charges (extracted from auction terms)
A22: Buyer's premium rate | B22: 0.165 | C22: Example only. Real rate extracted per auction.
A23: GST applies to hammer price | B23: Yes
A24: GST applies to buyer's premium | B24: Yes
A26: Other costs (enter GST inclusive amounts)
A27: Transport (estimate) | B27: 750
A28: Removal or crane | B28: 0
A29: Repairs | B29: 1500
A30: Replacement parts | B30: 0
A31: Testing or certification | B31: 0
A32: Cleaning and preparation | B32: 200
A33: Storage | B33: 0
A34: Selling fees | B34: 1480
A35: Other | B35: 0
A36: Total other costs | B36: =SUM(B27:B35) -> 3930
A37: Other costs include GST | B37: Yes | C37: Registered users can claim credits on GST inclusive costs.
A38: Effective other costs | B38: =IF(AND(B4="Yes",B37="Yes"),B36/(1+B5),B36) -> 3572.7273
A40: Cost per dollar of hammer price
A41: Hammer cost factor | B41: =1+IF(B4="Yes",0,IF(B23="Yes",B5,0)) -> 1 | C41: Unregistered buyers bear the GST as a real cost.
A42: Premium cost factor | B42: =B22*(1+IF(B4="Yes",0,IF(B24="Yes",B5,0))) -> 0.165
A43: Effective cost per $1 of hammer | B43: =B41+B42 -> 1.165
...

Sheet 11 Data Sources
A1: Data Sources
A2: Check each source's current terms and API access before build. Cost values are estimates.
A3: Source | B3: Role | C3: Access method | D3: Data obtained | E3: Terms and risk notes | F3: Legal risk | G3: Fallback
A4: Grays | B4: Auction catalogue | C4: Managed extraction (Firecrawl or Browserbase) | D4: Lots, photos, descriptions, location, closing time, current bid, premium terms | E4: Review terms. Public pages only, rate limited. | F4: Medium | G4: PDF upload
A5: Pickles | B5: Auction catalogue | C5: Managed extraction | D5: As above | E5: As above | F5: Medium | G5: PDF upload
A6: Lloyds | B6: Auction catalogue | C6: Managed extraction | D6: As above | E6: As above | F6: Medium | G6: PDF upload
A7: Auction PDF catalogues | B7: Auction catalogue | C7: PDF text extraction with OCR fallback, then Claude structuring | D7: Lots and descriptions. Photos where embedded. | E7: User supplied. Low risk. | F7: Low | G7: Manual lot entry
A8: Past auction results | B8: Sold evidence | C8: Managed extraction of published results pages where available | D8: Realised hammer prices | E8: Review terms per site. | F8: Medium | G8: Internal outcomes
A9: eBay Browse API | B9: Advertised evidence | C9: Official API | D9: Active listings, price, condition, location | E9: Official API terms. Low risk. | F9: Low | G9: Web search API
A10: eBay Marketplace Insights API | B10: Sold evidence | C10: Official API, restricted access | D10: Sold prices | E10: Requires eBay approval. Apply early. | F10: Low | G10: Auction results and internal outcomes
A11: Web search API (Brave or SerpAPI) | B11: Discovery | C11: Official API | D11: Retailer and dealer pages, new prices, specification pages | E11: Official API terms. | F11: Low | G11: Alternative search provider
A12: Retailer and dealer pages | B12: Advertised and new price evidence | C12: Fetch pages found through search, extract price and specs with Claude | D12: Advertised price, new price, specifications | E12: Respect robots and terms. Cache seven days. | F12: Medium | G12: Search snippet only, lower weight
A13: Manufacturer sites | B13: Specification and new price | C13: Fetch via search results | D13: Specs, RRP, model history | E13: Low | F13: Low | G13: Mark new price not found
A14: Internal outcomes | B14: Sold evidence | C14: Our own database | D14: Actual hammer and resale prices recorded by users | E14: Our data. Privacy policy must cover use. | F14: Low | G14: None needed
... A16: Routing API (Google Routes or Mapbox) | B16: Transport | C16: Official API | D16: Road distance between user base and lot location | E16: Official API terms. | F16: Low | G16: Straight line distance with uplift factor

Sheet 12 Pipeline
A1: Processing Pipeline
A2: Each stage is an Inngest or Trigger.dev function. Lots fan out as independent steps.
A3: Stage | B3: Name | C3: Trigger | D3: Work performed | E3: AI usage | F3: Writes to | G3: Typical duration
A4: S1 | B4: Ingest | C4: User submits URL or PDF | D4: Detect platform, create auction and analysis records, check triage allowance | E4: None | F4: auction, analysis | G4: Seconds
A5: S2 | B5: Extract | C5: S1 complete | D5: Fetch catalogue pages or parse PDF. Paginate. Store raw payload. | E5: Claude for PDF structuring only | F5: raw_extract | G5: 1 to 5 min
A6: S3 | B6: Normalise | C6: S2 complete | D6: Map to lot records. Download primary photo references. Parse premium and GST terms. | E6: Claude for premium terms parsing | F6: lot, lot_image, premium rule | G6: Under 1 min
A7: S4 | B7: Triage identify | C7: Per lot | D7: Classify category and product type from text and primary photo. | E7: Small model (Claude Haiku class) | F7: lot_identification (triage) | G7: Parallel
A8: S5 | B8: Triage value | C8: Per lot | D8: One search pass plus internal history lookup. Rough resale range. | E8: Small model to read results | F8: triage_valuation | G8: Parallel
A9: S6 | B9: Rank and notify | C9: All lots complete | D9: Rough max bid with the selected cost profile, opportunity score, email user. | E9: None | F9: Updated lots, notification | G9: Seconds
A10: S7 | B10: Shortlist | C10: User confirms selection | D10: Reserve credits in ledger, queue deep jobs. | E10: None | F10: credit_ledger entries | G10: Seconds
A11: S8 | B11: Deep identify | C11: Per shortlisted lot | D11: Read all photos including plates. Extract brand, model, year, specs, condition notes. | E11: Large model (Claude Sonnet class) with vision | F11: lot_identification (deep) | G11: Parallel
A12: S8A | B12: Enrich | C12: S8 complete and item identified | D12: Search manufacturer, dealer and specification sources for the identified model. Build field list with source class. Detect conflicts with the auctioneer description and photos. | E12: Large model to read and reconcile specification pages | F12: lot_spec_fields, product_spec_sources | G12: Parallel
A13: S9 | B13: Comparable search | C13: S8A complete | D13: Query eBay, search API, internal history and auction results. Fetch candidate pages. | E13: Small model to generate queries | F13: comparable, comparable_snapshot | G13: Parallel
A14: S10 | B14: Match grading | C14: S9 complete | D14: Assign match level, reason, differences and price adjustment to each comparable. | E14: Large model | F14: lot_comparable | G14: Parallel
... A19: S15 | B19: Closing alerts | C19: Scheduled | D19: Find watchlisted lots closing within the user's window and send alerts. | E19: None | F19: notification | G19: Every 5 min
A21: Design rules | B21: AI is used for reading, identifying and grading. All money maths is deterministic code, never AI. Every AI output is stored with the model name, prompt version and cost so results are reproducible and auditable.

Sheet 13 Database
A1: Database Schema (Supabase Postgres)
A2: All tables have created_at and updated_at timestamptz unless noted. Organisation scoped tables carry org_id for RLS.
A3: Table | B3: Purpose | C3: Column | D3: Type | E3: Nullable | F3: Keys | G3: Notes
A4: organisations | B4: Tenant. Everything belongs to an organisation. | C4: id | D4: uuid | E4: No | F4: PK | G4: Default gen_random_uuid()
A5: organisations | C5: name | D5: text | E5: No
A6: organisations | C6: plan | D6: text | E6: No | G6: free, starter, pro, dealer, internal
A7: organisations | C7: stripe_customer_id | D7: text | E7: Yes | G7: Phase 2
A8: organisations | C8: gst_registered | D8: boolean | E8: No | G8: Organisation level default
A9: organisations | C9: base_address | D9: text | E9: Yes | G9: Used for transport estimates
A10: organisations | C10: base_lat | D10: numeric | E10: Yes
A11: organisations | C11: base_lng | D11: numeric | E11: Yes
A12: profiles | B12: One row per auth user. | C12: id | D12: uuid | E12: No | F12: PK, FK auth.users
A13: profiles | C13: full_name | D13: text | E13: Yes
A14: profiles | C14: default_org_id | D14: uuid | E14: Yes | F14: FK organisations
A15: profiles | C15: alert_lead_minutes | D15: integer | E15: No | G15: Default 30
A16: organisation_members | B16: Membership and role. | C16: org_id | D16: uuid | E16: No | F16: PK, FK organisations
A17: organisation_members | C17: user_id | D17: uuid | E17: No | F17: PK, FK profiles
A18: organisation_members | C18: role | D18: text | E18: No | G18: owner, admin, buyer, viewer
A19: cost_profiles | B19: Saved default cost assumptions. | C19: id | D19: uuid | E19: No | F19: PK
A20: cost_profiles | C20: org_id | D20: uuid | E20: No | F20: FK organisations
A21: cost_profiles | C21: name | D21: text | E21: No | G21: For example Machinery
A22: cost_profiles | C22: is_default | D22: boolean | E22: No
A23: cost_profiles | C23: profit_mode | D23: text | E23: No | G23: dollars or percent
A24: cost_profiles | C24: target_profit_amount | D24: numeric(12,2) | E24: Yes
A25: cost_profiles | C25: target_return_pct | D25: numeric(6,4) | E25: Yes
A26: cost_profiles | C26: min_profit_amount | D26: numeric(12,2) | E26: Yes
A27: cost_profiles | C27: min_return_pct | D27: numeric(6,4) | E27: Yes
A28: cost_profiles | C28: transport_base_fee | D28: numeric(12,2) | E28: Yes
A29: cost_profiles | C29: transport_rate_per_km | D29: numeric(8,2) | E29: Yes
A30: cost_profiles | C30: repair_mode | D30: text | E30: No | G30: dollars or percent_of_resale
A31: cost_profiles | C31: repair_value | D31: numeric(12,4) | E31: Yes
A32: cost_profiles | C32: defaults | D32: jsonb | E32: No | G32: Other line item defaults keyed by cost field
A33: categories | B33: Category tree and category specific rules. | C33: id | D33: uuid | E33: No | F33: PK
A34: categories | C34: parent_id | D34: uuid | E34: Yes | F34: FK categories
A35: categories | C35: name | D35: text | E35: No
A36: categories | C36: asking_discount_pct | D36: numeric(6,4) | E36: No | G36: Default 0.10
A37: categories | C37: valuation_rules | D37: jsonb | E37: No | G37: Category specific rules added progressively
A38: auction_platforms | B38: Supported auction houses. | C38: id | D38: uuid | E38: No | F38: PK
A39: auction_platforms | C39: slug | D39: text | E39: No | F39: Unique | G39: grays, pickles, lloyds, pdf
A40: auction_platforms | C40: name | D40: text | E40: No
...

Sheet 14 Security
A1: Security and Row Level Security
A3: Area | B3: Applies to | C3: Rule
A4: Organisation scoped tables | B4: analyses, analysis_lots, lot_identifications, valuations, lot_costs, outcomes, cost_profiles, notifications, exports, credit_ledger | C4: Select, insert and update allowed where org_id is in the user's memberships. Helper function is_org_member(org_id).
A5: Shared tables | B5: auctions, lots, lot_images, products, product_aliases, comparables, comparable_snapshots, categories, auction_platforms | C5: Read for any signed in user. Write only by the service role through background jobs.
A6: Match table | B6: lot_comparables | C6: Readable when the linked identification belongs to the user's organisation. Written by service role. Users may update excluded_by_user only.
A7: Roles | B7: owner, admin, buyer, viewer | C7: Viewer read only. Buyer can edit costs, confirm identifications and spend credits. Admin manages members and profiles. Owner manages billing.
A8: Credits | B8: credit_ledger | C8: Insert only through a security definer function that checks balance atomically. No direct client writes.
A9: Service role | B9: Inngest or Trigger.dev functions | C9: Service key held only in server environment variables. Never sent to the browser.
A10: Storage | B10: PDF uploads and exports buckets | C10: Private buckets. Paths prefixed by org_id. Signed URLs with short expiry.
A11: Secrets | B11: API keys for Claude, search, extraction, routing, Stripe | C11: Stored in Vercel and job runner environments. Rotated on staff change.
A12: Privacy | B12: Outcomes and user data | C12: Pooled use of outcomes only with explicit consent flag. Privacy policy aligned to the Australian Privacy Principles.
A13: Abuse controls | B13: Submission endpoints | C13: Rate limit per organisation. Maximum lots per catalogue per tier. Bot protection on sign up.
A14: Platform settings | B14: platform_settings, platform_setting_changes, method_versions | C14: Read for signed in users. Write only by platform admins, with the change log written in the same transaction.
... A18: Terms | B18: terms_acceptances | C18: Insert own acceptance only. Middleware blocks app access when a material version is unaccepted.

Sheet 15 Tech Stack
A1: Technology Stack
A2: Confirm current pricing and limits for each service before build.
A3: Layer | B3: Choice | C3: Why | D3: Alternative
A4: Frontend | B4: Next.js App Router, TypeScript, Tailwind CSS, shadcn/ui | C4: Matches existing HSES Online skills | D4: Remix
A5: Tables | B5: TanStack Table | C5: Dense, sortable, filterable lot tables | D5: AG Grid
A6: Hosting | B6: Vercel | C6: Native Next.js hosting | D6: Netlify
A7: Database and auth | B7: Supabase Postgres, Auth, Storage, pgvector | C7: RLS for multi tenancy, vector search for product matching | D7: Neon plus Clerk
A8: Background jobs | B8: Inngest or Trigger.dev | C8: Durable steps, retries, fan out, schedules | D8: Supabase Queues
A9: AI | B9: Claude API. Haiku class for triage, Sonnet class for deep analysis and vision | C9: Strong vision and structured output | D9: Model agnostic layer later
A10: Page extraction | B10: Firecrawl or Browserbase | C10: Rendered pages without running our own browsers | D10: Self hosted Playwright
A11: PDF parsing | B11: Text extraction with OCR fallback, then Claude structuring | C11: Handles scanned catalogues | D11: Claude PDF input directly
A12: Web search | B12: Brave Search API or SerpAPI | C12: Predictable structured results | D12: Claude web search tool
A13: Marketplace data | B13: eBay Browse API, Marketplace Insights if approved | C13: Official access | D13: Search API results
A14: Routing | B14: Google Routes API or Mapbox | C14: Road distance for transport estimates | D14: OpenRouteService
... A18: Payments | B18: Stripe Billing (phase 2) | C18: Subscriptions, credits and top ups | D18: Paddle
A19: Monitoring | B19: Sentry | C19: Error tracking across app and jobs
A20: Analytics | B20: PostHog | C20: Product analytics and feature flags | D20: Plausible
A21: Development | B21: Claude Code and Codex, GitHub, GitHub Actions | C21: Existing workflow
A22: Testing | B22: Vitest for calculator maths, Playwright for end to end | C22: Bid maths must be tested to the cent
A23: Fonts | B23: next/font self hosting Barlow and Space Mono | C23: No layout shift, no third party font requests
A24: Monorepo | B24: Turborepo with pnpm workspaces | C24: Shared packages, cached builds, one repository | D24: Nx
A25: Component catalogue | B25: Storybook with the test runner and a11y addon | C25: Build and review components in isolation before pages | D25: Ladle
A26: Visual regression | B26: Chromatic, or Playwright screenshot tests | C26: Catches unintended visual changes per component | D26: Decide in O16
A27: Code size limits | B27: ESLint max-lines and max-lines-per-function rules | C27: Keeps every file small and editable
A28: Bundle budgets | B28: size-limit and Next.js bundle analyzer in CI | C28: Fails the build when a route grows past budget
A29: Installable web app | B29: Web app manifest with Serwist service worker | C29: Offline bid view and home screen install
A30: Agent rules | B30: CLAUDE.md and AGENTS.md at repo root | C30: Claude Code and Codex follow the same architecture rules
A31: Styling | B31: Tailwind CSS v4 with CSS variable tokens and restyled shadcn/ui | C31: One token set drives site and app, light and dark
A32: Marketing content | B32: MDX in the repo for static pages, database driven pages for guides and breakdowns | C32: Version controlled copy, programmatic scale | D32: Sanity or Payload CMS later
A33: Social images | B33: Next.js ImageResponse (Open Graph image generation) | C33: Branded share cards per page
A34: Search tooling | B34: Google Search Console, Bing Webmaster Tools, IndexNow | C34: Indexing and monitoring. Bing feeds several AI answer engines
A35: Accessibility testing | B35: axe core in Playwright runs and manual screen reader checks | C35: WCAG 2.2 AA enforced in CI

Sheet 16 Screens
A1: Screen Inventory
A3: ID | B3: Screen | C3: Purpose | D3: Key components | E3: Device
A4: SC01 | B4: Sign in | C4: Access | D4: Magic link, Google sign in | E4: Both
A5: SC02 | B5: Dashboard | C5: Recent analyses, watchlist closing soon, credit balance | D5: Analysis cards, closing countdown list, credit meter | E5: Desktop first
A6: SC03 | B6: New analysis | C6: Submit URL or PDF and choose cost profile | D6: URL field with platform detection, PDF drop zone, profile selector, triage allowance note | E6: Both
A7: SC04 | B7: Analysis progress | C7: Show extraction and triage progress | D7: Stage stepper, progress bar, leave page notice | E7: Both
A8: SC05 | B8: Triage table | C8: Rank and shortlist lots | D8: Dense table, opportunity score, rough range, rough max bid, filters, checkbox shortlist, credit preview bar | E8: Desktop first
A9: SC06 | B9: Lot detail | C9: Deep analysis result for one lot | D9: Photo strip, identification card with confirm and edit, valuation band, confidence badge, bid limits, calculator | E9: Desktop first
A10: SC06A | B10: Spec sheet section | C10: Enriched specifications for the lot | D10: Four source class groups, optional equipment checklist, conflict flags, source links, Report a problem, download PDF | E10: Desktop first
A11: SC07 | B11: Evidence panel | C11: Show comparables | D11: Comparable rows with match level badge, reason, differences, price, date checked, link, exclude toggle | E11: Desktop first
A12: SC08 | B12: Calculator panel | C12: Costs and profit | D12: Collapsed cost summary with expand, profit mode toggle, bid slider with green, amber and red zones, cash required and effective cost | E12: Both
A13: SC09 | B13: Watchlist | C13: Track lots across auctions | D13: List with countdown, target and absolute maximum, alert settings | E13: Both
A14: SC10 | B14: Mobile bid view | C14: Use while bidding | D14: One lot per card, very large target and maximum figures, stop line, swipe between lots | E14: Mobile
... A21: SC17 | B21: Try before sign up result | C21: Sample triage for anonymous visitors | D21: Top lots from a cached triage, blurred remainder, sign up call to action, DS21 note | E21: Both

Sheet 17 Design System
A1: Design System
A2: Blueprint direction. Light pages, navy panels, data dense and precise. Signed off 22 September 2026.
A3: Principles | B3: Numbers first. Calm neutral surfaces. Colour used only for meaning: profit zones, confidence and match levels. Every figure shows its basis on hover or tap.
A4: Typography | B4: Barlow 700 to 800 for headings and bid figures. Barlow 400 to 600 for body and interface text, with tabular figures on all numbers. Space Mono for lot numbers, model codes and uppercase data labels. Base size 15px on desktop tables, 16px on mobile, 48px or larger for bid figures in the phone bid view. Full brand system on tab 33.
A5: Density | B5: Table rows 36px on desktop with a comfortable option at 44px. Sticky table header and first column.
A6: Numbers | B6: Whole dollars in tables, cents only in the calculator detail. Negative values in red with a minus sign replaced by parentheses in exports.
A7: Accessibility | B7: WCAG 2.2 AA contrast on light pages and navy panels. Status never shown by colour alone: every zone and badge carries a text label.
A9: Token | B9: Use | C9: Light pages | D9: On navy panels | E9: Notes
A10: background | B10: Page background | C10: #F4F7FA | E10: Drafting white
A11: surface | B11: Cards, tables and search panel | C11: #FFFFFF | D11: #0E2A47 | E11: Navy is the panel colour for headers, bid limits and sign up
A12: surface_muted | B12: Table headers on light, photo placeholders, chips | C12: #E6EDF4 | D12: rgba(255,255,255,0.14)
A13: border | B13: Hairlines and dividers | C13: #C9D6E3 | D13: #7FC8F8 at 50 percent | E13: Double inset frame lines on navy panels
A14: ink | B14: Primary text | C14: #0E1B2B | D14: #FFFFFF
A15: ink_muted | B15: Secondary text and notes | C15: #4A5A6D | D15: #B7CDE3 | E15: Disclaimer notes use this
A16: accent | B16: Marker yellow. Primary buttons, stop line, most you should bid | C16: #FFD23F fill with #0E1B2B text | D16: #FFD23F fill with #0E1B2B text | E16: Never used for status or as text colour
A17: line | B17: Drafting lines and labels on navy | D17: #7FC8F8 | E17: Title blocks, mono labels, frame lines
A18: link | B18: Links, icons, index numbers | C18: #1B6FD1 | D18: #7FC8F8
A19: zone_green | B19: Meets profit target | C19: #1E7A52 | D19: #6EE7B7 | E19: Label: On target
A20: zone_amber | B20: Profitable, below target | C20: #B45309 | D20: #FBBF24 | E20: Label: Below target. Distinct from marker yellow
A21: zone_red | B21: Break even or loss | C21: #B91C1C | D21: #F87171 | E21: Label: Loss risk
A22: tag_verified | B22: Verified tag | C22: #1E7A52 fill, white text
A23: tag_extracted | B23: Extracted tag | C23: #E6EDF4 fill, ink text
A24: tag_estimated | B24: Estimated tag | C24: #FFF4CC fill, ink text
A25: tag_your_input | B25: Your input tag | C25: #1B6FD1 fill, white text
A26: confidence_high | B26: High confidence | C26: #1E7A52 | D26: #6EE7B7
A27: confidence_medium | B27: Medium confidence | C27: #0E1B2B | D27: #FFFFFF
A28: confidence_low | B28: Low confidence | C28: #B45309 | D28: #FBBF24
A29: confidence_insufficient | B29: Not enough evidence | C29: #6B7280 | D29: #9CA3AF
A31: Component | B31: Specification
A32: Match level badge | B32: Pill with icon and text. Exact and Near exact solid. Spec and alternative outlined. Insufficient grey.
A33: Confidence badge | B33: Pill with label and score on hover.
A34: Bid slider | B34: Track coloured by zone with markers at target, absolute maximum and break even. Live readout of profit and return.
A35: Cost summary | B35: One line total with a chevron to expand line items. Flag icon when selling fees are blank.
A36: Evidence row | B36: Source, price, date checked, match badge, one line reason, expand for differences, external link icon.
A37: Stop line | B37: Marker yellow bar at the break even price, with a yellow Stop bidding panel in the phone bid view.

Sheet 18 Commercial
A1: Commercial Model
A2: Indicative pricing in AUD excluding GST. Validate after the internal MVP. One credit equals one deep analysed lot.
A3: Tier | B3: Monthly price ($) | C3: Triage catalogues per month | D3: Deep credits per month | E3: Seats | F3: Includes | G3: Target persona
A4: Free | B4: 0 | C4: 1 | D4: 5 | E4: 1 | F4: Triage, limited deep analysis, watchlist | G4: Entry point
A5: Starter | B5: 79 | C5: 5 | D5: 40 | E5: 1 | F5: All V1 features, PDF bid sheet, alerts | G5: Part time reseller
A6: Pro | B6: 199 | C6: 12 | D6: 100 | E6: 3 | F6: Everything in Starter, CSV export, outcome analytics | G6: Full time flipper
A7: Dealer | B7: 699 | C7: 40 | D7: 400 | E7: 10 | F7: Everything in Pro, team roles, priority processing | G7: Dealers and liquidators
A9: Top up pack | B9: Credits | C9: Price ($) | D9: Price per credit
A10: Top up small | B10: 25 | C10: 39 | D10: =C10/B10 -> 1.56
A11: Top up large | B11: 100 | C11: 129 | D11: =C11/B11 -> 1.29
A13: Credit rules | B13: Credits reserved when deep analysis starts and settled on completion. Failed lots are refunded automatically. Revaluation after a correction is free when cached comparables are reused and costs one credit when a new search is needed.
A14: Rollover | B14: Unused plan credits roll over for one month. Top up credits last twelve months.
A15: Annual plans | B15: Two months free on annual billing.
A16: Pricing rule | B16: Price per credit must stay well above the deep analysis cost per lot on tab 19. Every tier should hold at least 30 percent gross margin at full usage. First draft prices failed this test and were revised.

Sheet 19 Unit Economics
A1: Unit Economics
A2: All cost inputs are estimates in AUD. Replace with logged actuals from ai_runs and usage_events during the MVP.
A3: Inputs
